Workbook

Sheet 10.24右线模板新
A1: YKZ4 | B1: 11.0394
A2: YBM8 | B2: 10.3774 | C2: 0.0441
A3: YBM7 | B3: 10.36561 | C3: 0.342
A4: YBM6 | B4: 10.35875 | C4: 0.0108
A5: YBM5 | B5: 10.36959 | C5: 0.0109
A6: 5 | B6: 10.33393 | C6: 0.057
A7: YDDC26-1 | B7: =IFERROR(VLOOKUP(TRIM(A7),数据!$A:$GD,4,FALSE),B7) -> 10.3241 | C7: 5.1566 | D7: Z
A8: YDDC26-2 | B8: =IFERROR(VLOOKUP(TRIM(A8),数据!$A:$GD,4,FALSE),B8) -> 10.34604 | C8: 6.1817 | D8: Z
A9: YDDC26-3 | B9: =IFERROR(VLOOKUP(TRIM(A9),数据!$A:$GD,4,FALSE),B9) -> 10.34702 | C9: 5.2177 | D9: Z
A10: YDDC27-1 | B10: =IFERROR(VLOOKUP(TRIM(A10),数据!$A:$GD,4,FALSE),B10) -> 10.36692 | C10: 5.5919 | D10: Z
A11: YDDC27-2 | B11: =IFERROR(VLOOKUP(TRIM(A11),数据!$A:$GD,4,FALSE),B11) -> 10.35644 | C11: 6.1411 | D11: Z
A12: YDDC27-3 | B12: =IFERROR(VLOOKUP(TRIM(A12),数据!$A:$GD,4,FALSE),B12) -> 10.36955 | C12: 3.2478 | D12: Z
A13: YDDC27-4 | B13: =IFERROR(VLOOKUP(TRIM(A13),数据!$A:$GD,4,FALSE),B13) -> 10.36498 | C13: 5.4687 | D13: Z
A14: YDDC28-1 | B14: =IFERROR(VLOOKUP(TRIM(A14),数据!$A:$GD,4,FALSE),B14) -> 10.35475 | C14: 6.0207 | D14: Z
A15: YDDC28-2 | B15: =IFERROR(VLOOKUP(TRIM(A15),数据!$A:$GD,4,FALSE),B15) -> 10.36201 | C15: 4.7961 | D15: Z
A16: YDDC28-3 | B16: =IFERROR(VLOOKUP(TRIM(A16),数据!$A:$GD,4,FALSE),B16) -> 10.34223 | C16: 4.9983 | D16: Z
A17: YDDC29-1 | B17: =IFERROR(VLOOKUP(TRIM(A17),数据!$A:$GD,4,FALSE),B17) -> 10.35892 | C17: 5.9984 | D17: Z
A18: YDDC29-2 | B18: =IFERROR(VLOOKUP(TRIM(A18),数据!$A:$GD,4,FALSE),B18) -> 9.93579 | C18: 3.0673 | D18: Z
... A25: YDDC31-2 | B25: =IFERROR(VLOOKUP(TRIM(A25),数据!$A:$GD,4,FALSE),B25) -> 9.99417 | C25: 2.9858 | D25: Z
A26: 6 | B26: 10.23559 | C26: 0.0527
A27: YDDC16-1 | B27: =IFERROR(VLOOKUP(TRIM(A27),数据!$A:$GD,4,FALSE),B27) -> 10.16519 | C27: 5.3074 | D27: Z
A28: YDDC16-2 | B28: =IFERROR(VLOOKUP(TRIM(A28),数据!$A:$GD,4,FALSE),B28) -> 10.19097 | C28: 5.3299 | D28: Z
A29: YDDC16-3 | B29: =IFERROR(VLOOKUP(TRIM(A29),数据!$A:$GD,4,FALSE),B29) -> 10.1986 | C29: 5.5993 | D29: Z
A30: YDDC17-1 | B30: =IFERROR(VLOOKUP(TRIM(A30),数据!$A:$GD,4,FALSE),B30) -> 10.21838 | C30: 3.7273 | D30: Z
A31: YDDC17-2 | B31: =IFERROR(VLOOKUP(TRIM(A31),数据!$A:$GD,4,FALSE),B31) -> 10.19049 | C31: 2.9014 | D31: Z
A32: YDDC17-3 | B32: =IFERROR(VLOOKUP(TRIM(A32),数据!$A:$GD,4,FALSE),B32) -> 10.12461 | C32: 3.0081 | D32: Z
A33: YDDC18-1 | B33: =IFERROR(VLOOKUP(TRIM(A33),数据!$A:$GD,4,FALSE),B33) -> 10.14344 | C33: 5.0652 | D33: Z
A34: YDDC18-3 | B34: =IFERROR(VLOOKUP(TRIM(A34),数据!$A:$GD,4,FALSE),B34) -> 10.15822 | C34: 5.2358 | D34: Z
A35: YDDC19-1 | B35: =IFERROR(VLOOKUP(TRIM(A35),数据!$A:$GD,4,FALSE),B35) -> 10.15906 | C35: 5.6857 | D35: Z
A36: YDDC19-2 | B36: =IFERROR(VLOOKUP(TRIM(A36),数据!$A:$GD,4,FALSE),B36) -> 10.16717 | C36: 5.0984 | D36: Z
A37: YDDC19-3 | B37: =IFERROR(VLOOKUP(TRIM(A37),数据!$A:$GD,4,FALSE),B37) -> 10.17294 | C37: 5.6177 | D37: Z
A38: YDDC20-1 | B38: =IFERROR(VLOOKUP(TRIM(A38),数据!$A:$GD,4,FALSE),B38) -> 10.1741 | C38: 6.0087 | D38: Z
... A59: YDDC25-4 | B59: =IFERROR(VLOOKUP(TRIM(A59),数据!$A:$GD,4,FALSE),B59) -> 10.34032 | C59: 3.171 | D59: Z
A60: 7 | B60: 10.12798 | C60: 0.0525
A61: YDDC10-1 | B61: =IFERROR(VLOOKUP(TRIM(A61),数据!$A:$GD,4,FALSE),B61) -> 10.04387 | C61: 5.0049 | D61: Z
A62: YDDC10-2 | B62: =IFERROR(VLOOKUP(TRIM(A62),数据!$A:$GD,4,FALSE),B62) -> 10.02851 | C62: 5.2129 | D62: Z
A63: YDDC11-1 | B63: =IFERROR(VLOOKUP(TRIM(A63),数据!$A:$GD,4,FALSE),B63) -> 10.04586 | C63: 5.5917 | D63: Z
A64: YDDC11-2 | B64: =IFERROR(VLOOKUP(TRIM(A64),数据!$A:$GD,4,FALSE),B64) -> 10.04704 | C64: 3.6165 | D64: Z
A65: YDDC12-1 | B65: =IFERROR(VLOOKUP(TRIM(A65),数据!$A:$GD,4,FALSE),B65) -> 10.06931 | C65: 3.3237 | D65: Z
A66: YDDC12-2 | B66: =IFERROR(VLOOKUP(TRIM(A66),数据!$A:$GD,4,FALSE),B66) -> 10.08344 | C66: 3.1107 | D66: Z
...

Sheet 高程
B1: 45954 | C1: 45961 | D1: 45968 | E1: 45975 | F1: 45980 | G1: 45981 | H1: 45982 | I1: 45983 | J1: 45986 | K1: 45989 | L1: 45992 | M1: 45995 | N1: 45998 | O1: 46001 | P1: 46004 | Q1: 46005 | R1: 2025/12/14晚 | S1: 46006 | T1: 2025/12/15晚 | U1: 46007 | V1: 2025/12/16晚 | W1: 46008 | X1: 2025/12/17晚 | Y1: 46009 | Z1: 2025/12/18晚 | AA1: 46010 | AB1: 2025/12/19晚 | AC1: 46011 | AD1: 2025/12/20晚 | AE1: 46012 | AF1: 2025/12/21晚 | AG1: 46013 | AH1: 2025/12/22晚 | AI1: 46014 | AJ1: 2025/12/23晚 | AK1: 46015 | AL1: 2025/12/24晚 | AM1: 46016 | AN1: 2025/12/25晚 | AO1: 46017 | AP1: 2025/12/26晚 | AQ1: 46018 | AR1: 2025/12/27晚 | AS1: 46019 | AT1: 2025/12/28晚 | AU1: 46020 | AV1: 2025/12/29晚 | AW1: 46021 | AX1: 2025/12/30晚 | AY1: 46022 | AZ1: 2025/12/31晚 | BA1: 46023 | BB1: 1/1晚 | BC1: 46024 | BD1: 1/2晚 | BE1: 46025 | BF1: 1/3晚 | BG1: 46026 | BH1: 1/4晚 | BI1: 46027 | BJ1: 1/5晚 | BK1: 46028 | BL1: 1/6晚 | BM1: 46029 | BN1: 1/7晚 | BO1: 46030 | BP1: 1/8晚 | BQ1: 46031 | BR1: 1/9晚 | BS1: 46032 | BT1: 1/10晚 | BU1: 46033 | BV1: 1/11晚 | BW1: 46034 | BX1: 1/12晚 | BY1: 46035 | BZ1: 1/13晚 | CA1: 46036 | CB1: 1/14晚 | CC1: 46037 | CD1: 1/15晚 | CE1: 46038 | CF1: 1/16晚 | CG1: 46039 | CH1: 1/17晚 | CI1: 46040 | CJ1: 1/18晚 | CK1: 46041 | CL1: 1/19晚 | CM1: 46042 | CN1: 1/20晚 | CO1: 46043 | CP1: 1/21晚 | CQ1: 46044 | CR1: 1/22晚 | CS1: 46045 | CT1: 1/23晚 | CU1: 46046 | CV1: 1/24晚 | CW1: 46047 | CX1: 1/25晚 | CY1: 46048 | CZ1: 46049 | DA1: 46050 | DB1: 46051 | DC1: 46052 | DD1: 46053 | DE1: 46054 | DF1: 46055 | DG1: 46056 | DH1: 46080 | DI1: 46081 | DJ1: 46082 | DK1: 46083 | DL1: 46084 | DM1: 46085 | DN1: 46086 | DO1: 46087 | DP1: 46088 | DQ1: 46089 | DR1: 46090 | DS1: 46091 | DT1: 46092 | DU1: 46093 | DV1: 46094 | DW1: 46095 | DX1: 46096 | DY1: 46097 | EB1: 初值 | EC1: 46098 | ED1: 46099 | EE1: 46100 | EF1: 46101 | EG1: 46102 | EH1: 46103 | EI1: 46104 | EJ1: 46105 | EK1: 46106 | EL1: 46107 | EM1: 46108 | EN1: 46109 | EO1: 46110 | EP1: 46111 | EQ1: 46112 | ER1: 46113 | ES1: 46114 | ET1: 46115 | EU1: 46116 | EV1: 46117 | EW1: 46118 | EX1: 46119 | EY1: 46120 | EZ1: 46121 | FA1: 46122 | FB1: 46123 | FC1: 46124 | FD1: 46125 | FE1: 46126 | FF1: 46127 | FG1: 2026/4/15人工 | FH1: 46128 | FI1: 46129 | FJ1: 46130 | FK1: 46131 | FL1: 46132 | FM1: 2026/4/20人工 | FN1: 46133 | FO1: 46134 | FP1: 46135 | FQ1: 46136 | FR1: 46137 | FS1: 46138 | FT1: 46139 | FU1: 2026/4/28人工 | FV1: 46141 | FW1: 46142 | FX1: 46143 | FY1: 46144 | FZ1: 46145 | GA1: 46146 | GB1: 46147 | GC1: 46148 | GD1: 46149 | GE1: 46150 | GF1: 46151 | GG1: 46152 | GH1: 46153 | GI1: 46154 | GJ1: 46155 | GK1: 46156
A2: YJGC1-1 | B2: 10.13745 | C2: 10.13737 | D2: 10.13732 | E2: 10.13743 | F2: 10.13741 | G2: 10.13744 | H2: 10.13744 | I2: 10.13744 | J2: 10.1373 | K2: 10.13746 | L2: 10.13735 | M2: 10.13734 | N2: 10.13734 | O2: 10.13734 | P2: 10.1402 | Q2: 10.14027 | R2: 10.139657 | S2: 10.13693 | T2: 10.13692 | U2: 10.13711 | V2: 10.13693 | W2: 10.1389 | X2: 10.13888 | Y2: 10.13888 | Z2: 10.13888 | AA2: 10.13859 | AB2: 10.1383 | AC2: 10.13831 | AD2: 10.13832 | AE2: 10.13871 | AF2: 10.1391 | AG2: 10.13912 | AH2: 10.13914 | AI2: 10.13942 | AJ2: 10.1397 | AK2: 10.13969 | AL2: 10.13966 | AM2: 10.1396 | AN2: 10.13953 | AO2: 10.13972 | AP2: 10.1399 | AQ2: 10.1401 | AR2: 10.13983 | AS2: 10.13992 | AT2: 10.13966 | AU2: 10.13974 | AV2: 10.13966 | AW2: 10.13949 | AX2: 10.13963 | AY2: 10.13952 | AZ2: 10.13971 | BA2: 10.13956 | BB2: 10.13944 | BC2: 10.13976 | BD2: 10.13964 | BE2: 10.1397 | BF2: 10.13955 | BG2: 10.13955 | BH2: 10.13955 | BI2: 10.13966 | BJ2: 10.13971 | BK2: 10.13967 | BL2: 10.13962 | BM2: 10.13972 | BN2: 10.13982 | BO2: 10.1398 | BP2: 10.13979 | BQ2: 10.13971 | BR2: 10.13987 | BS2: 10.13972 | BT2: 10.13973 | BU2: 10.13975 | BV2: 10.13977 | BW2: 10.13979 | BX2: 10.1398 | BY2: 10.13985 | BZ2: 10.1396 | CA2: 10.13944 | CB2: 10.13969 | CC2: 10.13968 | CD2: 10.13971 | CE2: 10.13976 | CF2: 10.13958 | CG2: 10.13967 | CH2: 10.13961 | CI2: 10.13969 | CJ2: 10.13949 | CK2: 10.13955 | CL2: 10.1396 | CM2: 10.13959 | CN2: 10.13966 | CO2: 10.13964 | CP2: 10.13956 | CQ2: 10.13949 | CR2: 10.13964 | CS2: 10.13948 | CT2: 10.13948 | CU2: 10.13956 | CV2: 10.13943 | CW2: 10.13953 | CX2: 10.1394 | CY2: 10.13943 | CZ2: 10.13949 | DA2: 10.13934 | DB2: 10.13972 | DC2: 10.1401 | DD2: 10.14006 | DE2: 10.14006 | DF2: 10.13994 | DG2: 10.13989 | DH2: 10.13973 | DI2: 10.13971 | DJ2: 10.13965 | DK2: 10.1397 | DL2: 10.1396 | DM2: 10.13963 | DN2: 10.13982 | DO2: 10.13968 | DP2: 10.13965 | DQ2: 10.13977 | DR2: 10.1397 | DS2: 10.1398 | DT2: 10.13975 | DU2: 10.13962 | DV2: 10.13971 | DW2: 10.13969 | DX2: 10.13988 | DY2: 10.13984 | EA2: YJGS1.1 | EB2: 10.2566 | EC2: 10.25645 | ED2: 10.25649 | EE2: 10.2566 | EF2: 10.25687 | EG2: 10.25668 | EH2: 10.25657 | EI2: 10.25687 | EJ2: 10.2572 | EK2: 10.25693 | EL2: 10.25656 | EM2: 10.13977 | EN2: 10.25684 | EO2: 10.2569 | EP2: 10.25699 | EQ2: 10.25715 | ER2: 10.25725 | ES2: 10.25681 | ET2: 10.13962 | EU2: 10.25628 | EV2: 10.25644 | EW2: 10.25659 | EX2: 10.25613 | EY2: 10.25612 | EZ2: 10.25572 | FA2: 10.1398 | FB2: 10.25604 | FC2: 10.2561 | FD2: 10.25644 | FE2: 10.25654 | FF2: 10.25656 | FG2: 10.13964 | FH2: 10.2565 | FI2: 10.25621 | FJ2: 10.25616 | FK2: 10.25633 | FL2: 10.25627 | FM2: 10.13971 | FN2: 10.25592 | FO2: 10.256 | FP2: 10.25597 | FQ2: 10.25594 | FR2: 10.25596 | FS2: 10.25603 | FT2: 10.25598 | FU2: 10.13969 | FV2: 10.25623 | FW2: 10.25621 | FX2: 10.13983 | FY2: 10.2559 | FZ2: 10.2559 | GA2: 10.25617 | GB2: 10.25607 | GC2: 10.2559 | GD2: 10.25603
A3: YJGC1-2 | B3: 10.2154 | C3: 10.21534 | D3: 10.21526 | E3: 10.21538 | F3: 10.21531 | G3: 10.21533 | H3: 10.21541 | I3: 10.21536 | J3: 10.21529 | K3: 10.21525 | L3: 10.21527 | M3: 10.21521 | N3: 10.21522 | O3: 10.21521 | P3: 10.2191 | Q3: 10.21909 | R3: 10.218613 | S3: 10.21625 | T3: 10.21613 | U3: 10.21641 | V3: 10.21628 | W3: 10.2185 | X3: 10.21866 | Y3: 10.2187 | Z3: 10.21873 | AA3: 10.21847 | AB3: 10.2182 | AC3: 10.2183 | AD3: 10.21839 | AE3: 10.21865 | AF3: 10.2189 | AG3: 10.219 | AH3: 10.21909 | AI3: 10.2195 | AJ3: 10.2199 | AK3: 10.21987 | AL3: 10.2197 | AM3: 10.21925 | AN3: 10.2188 | AO3: 10.21915 | AP3: 10.2195 | AQ3: 10.21954 | AR3: 10.21957 | AS3: 10.21947 | AT3: 10.21942 | AU3: 10.21952 | AV3: 10.21952 | AW3: 10.21958 | AX3: 10.2197 | AY3: 10.21972 | AZ3: 10.2196 | BA3: 10.2196 | BB3: 10.21986 | BC3: 10.21984 | BD3: 10.21967 | BE3: 10.21968 | BF3: 10.21957 | BG3: 10.21982 | BH3: 10.21993 | BI3: 10.2198 | BJ3: 10.21974 | BK3: 10.21972 | BL3: 10.21969 | BM3: 10.2196 | BN3: 10.21951 | BO3: 10.21947 | BP3: 10.21945 | BQ3: 10.21953 | BR3: 10.21965 | BS3: 10.21957 | BT3: 10.21965 | BU3: 10.21963 | BV3: 10.2196 | BW3: 10.21965 | BX3: 10.2197 | BY3: 10.21958 | BZ3: 10.2195 | CA3: 10.21948 | CB3: 10.21936 | CC3: 10.21917 | CD3: 10.21931 | CE3: 10.21938 | CF3: 10.21922 | CG3: 10.21908 | CH3: 10.21923 | CI3: 10.21907 | CJ3: 10.21923 | CK3: 10.21922 | CL3: 10.2192 | CM3: 10.21908 | CN3: 10.21912 | CO3: 10.21897 | CP3: 10.21904 | CQ3: 10.21896 | CR3: 10.21911 | CS3: 10.21887 | CT3: 10.21906 | CU3: 10.21889 | CV3: 10.21895 | CW3: 10.21911 | CX3: 10.21896 | CY3: 10.21898 | CZ3: 10.21891 | DA3: 10.21905 | DB3: 10.21953 | DC3: 10.22 | DD3: 10.21983 | DE3: 10.2199 | DF3: 10.21991 | DG3: 10.21984 | DH3: 10.21951 | DI3: 10.21969 | DJ3: 10.21955 | DK3: 10.21962 | DL3: 10.21943 | DM3: 10.21965 | DN3: 10.21956 | DO3: 10.21953 | DP3: 10.2196 | DQ3: 10.21951 | DR3: 10.21937 | DS3: 10.21942 | DT3: 10.21944 | DU3: 10.21955 | DV3: 10.21965 | DW3: 10.21965 | DX3: 10.21958 | DY3: 10.21943 | EA3: YJGS1.2 | EB3: 10.91831 | EC3: 10.91815 | ED3: 10.91844 | EE3: 10.91847 | EF3: 10.91876 | EG3: 10.9187 | EH3: 10.91877 | EI3: 10.91853 | EJ3: 10.91897 | EK3: 10.91856 | EL3: 10.91855 | EM3: 10.21963 | EN3: 10.91833 | EO3: 10.91853 | EP3: 10.9182 | EQ3: 10.91787 | ER3: 10.91824 | ES3: 10.91791 | ET3: 10.21942 | EU3: 10.91857 | EV3: 10.91861 | EW3: 10.91836 | EX3: 10.91795 | EY3: 10.918 | EZ3: 10.91759 | FA3: 10.21961 | FB3: 10.9178 | FC3: 10.91819 | FD3: 10.91845 | FE3: 10.9187 | FF3: 10.91839 | FG3: 10.21936 | FH3: 10.91867 | FI3: 10.91855 | FJ3: 10.91811 | FK3: 10.91821 | FL3: 10.91811 | FM3: 10.21938 | FN3: 10.91852 | FO3: 10.9189 | FP3: 10.91884 | FQ3: 10.91862 | FR3: 10.91844 | FS3: 10.91864 | FT3: 10.91845 | FU3: 10.21956 | FV3: 10.91821 | FW3: 10.9179 | FX3: 10.21938 | FY3: 10.9181 | FZ3: 10.91822 | GA3: 10.91793 | GB3: 10.91797 | GC3: 10.91822 | GD3: 10.91832
A4: YJGC2-1 | B4: 10.13865 | C4: 10.13853 | D4: 10.1385 | E4: 10.13864 | F4: 10.13859 | G4: 10.13863 | H4: 10.13851 | I4: 10.13864 | J4: 10.13862 | K4: 10.13856 | L4: 10.13857 | M4: 10.13845 | N4: 10.13847 | O4: 10.13845 | P4: 10.1424 | Q4: 10.14248 | R4: 10.141821 | S4: 10.13941 | T4: 10.13923 | U4: 10.13955 | V4: 10.13947 | W4: 10.1412 | X4: 10.14139 | Y4: 10.14138 | Z4: 10.14137 | AA4: 10.14129 | AB4: 10.1412 | AC4: 10.1413 | AD4: 10.14139 | AE4: 10.1416 | AF4: 10.1418 | AG4: 10.14177 | AH4: 10.14173 | AI4: 10.14202 | AJ4: 10.1423 | AK4: 10.14214 | AL4: 10.14222 | AM4: 10.14181 | AN4: 10.1414 | AO4: 10.14175 | AP4: 10.1421 | AQ4: 10.14219 | AR4: 10.14208 | AS4: 10.14209 | AT4: 10.14203 | AU4: 10.14212 | AV4: 10.14212 | AW4: 10.14221 | AX4: 10.14223 | AY4: 10.14238 | AZ4: 10.14212 | BA4: 10.14227 | BB4: 10.14231 | BC4: 10.14234 | BD4: 10.14211 | BE4: 10.14224 | BF4: 10.14216 | BG4: 10.14234 | BH4: 10.14242 | BI4: 10.14245 | BJ4: 10.14246 | BK4: 10.14247 | BL4: 10.14247 | BM4: 10.14252 | BN4: 10.14256 | BO4: 10.14204 | BP4: 10.14182 | BQ4: 10.14169 | BR4: 10.14187 | BS4: 10.14169 | BT4: 10.14191 | BU4: 10.14184 | BV4: 10.14177 | BW4: 10.14189 | BX4: 10.142 | BY4: 10.14195 | BZ4: 10.142 | CA4: 10.14198 | CB4: 10.14186 | CC4: 10.14167 | CD4: 10.14178 | CE4: 10.14171 | CF4: 10.14164 | CG4: 10.14159 | CH4: 10.14172 | CI4: 10.14156 | CJ4: 10.14159 | CK4: 10.14185 | CL4: 10.142 | CM4: 10.14203 | CN4: 10.14203 | CO4: 10.14192 | CP4: 10.14197 | CQ4: 10.14206 | CR4: 10.14196 | CS4: 10.1418 | CT4: 10.14188 | CU4: 10.14181 | CV4: 10.14181 | CW4: 10.14178 | CX4: 10.14202 | CY4: 10.14208 | CZ4: 10.1419 | DA4: 10.142 | DB4: 10.1423 | DC4: 10.1426 | DD4: 10.14255 | DE4: 10.14268 | DF4: 10.14248 | DG4: 10.1427 | DH4: 10.14296 | DI4: 10.14305 | DJ4: 10.14298 | DK4: 10.14293 | DL4: 10.14287 | DM4: 10.14303 | DN4: 10.14299 | DO4: 10.14286 | DP4: 10.14295 | DQ4: 10.14298 | DR4: 10.14291 | DS4: 10.14307 | DT4: 10.14299 | DU4: 10.14288 | DV4: 10.14309 | DW4: 10.14305 | DX4: 10.14284 | DY4: 10.14309 | EA4: YJGS2.1 | EB4: 10.0191 | EC4: 10.01925 | ED4: 10.01902 | EE4: 10.01889 | EF4: 10.01859 | EG4: 10.01845 | EH4: 10.01841 | EI4: 10.01841 | EJ4: 10.01867 | EK4: 10.01847 | EL4: 10.01871 | EM4: 10.14287 | EN4: 10.01931 | EO4: 10.01938 | EP4: 10.01924 | EQ4: 10.01932 | ER4: 10.01937 | ES4: 10.01909 | ET4: 10.14305 | EU4: 10.01857 | EV4: 10.01857 | EW4: 10.01877 | EX4: 10.01887 | EY4: 10.01889 | EZ4: 10.01851 | FA4: 10.14307 | FB4: 10.0186 | FC4: 10.01904 | FD4: 10.01907 | FE4: 10.01875 | FF4: 10.01874 | FG4: 10.14282 | FH4: 10.01865 | FI4: 10.01875 | FJ4: 10.01887 | FK4: 10.01875 | FL4: 10.01867 | FM4: 10.14306 | FN4: 10.01868 | FO4: 10.01871 | FP4: 10.01901 | FQ4: 10.01923 | FR4: 10.01948 | FS4: 10.01966 | FT4: 10.01979 | FU4: 10.14302 | FV4: 10.01939 | FW4: 10.01951 | FX4: 10.14283 | FY4: 10.01951 | FZ4: 10.01939 | GA4: 10.01932 | GB4: 10.01959 | GC4: 10.01939 | GD4: 10.01948
A5: YJGC2-2 | B5: 10.2084 | C5: 10.2083 | D5: 10.20826 | E5: 10.20838 | F5: 10.20832 | G5: 10.2083 | H5: 10.20826 | I5: 10.20833 | J5: 10.20834 | K5: 10.20836 | L5: 10.20834 | M5: 10.20829 | N5: 10.2084 | O5: 10.20829 | P5: 10.2125 | Q5: 10.21253 | R5: 10.212176 | S5: 10.20979 | T5: 10.20978 | U5: 10.2098 | V5: 10.20975 | W5: 10.2116 | X5: 10.21176 | Y5: 10.21182 | Z5: 10.21187 | AA5: 10.21174 | AB5: 10.2116 | AC5: 10.21162 | AD5: 10.21163 | AE5: 10.21192 | AF5: 10.2122 | AG5: 10.21224 | AH5: 10.21227 | AI5: 10.21249 | AJ5: 10.2127 | AK5: 10.21255 | AL5: 10.21286 | AM5: 10.21238 | AN5: 10.2119 | AO5: 10.21225 | AP5: 10.2126 | AQ5: 10.21241 | AR5: 10.21264 | AS5: 10.21254 | AT5: 10.21252 | AU5: 10.21271 | AV5: 10.21265 | AW5: 10.21272 | AX5: 10.21253 | AY5: 10.21247 | AZ5: 10.21264 | BA5: 10.21238 | BB5: 10.21252 | BC5: 10.21264 | BD5: 10.21246 | BE5: 10.21255 | BF5: 10.21246 | BG5: 10.21249 | BH5: 10.2125 | BI5: 10.21262 | BJ5: 10.21267 | BK5: 10.21261 | BL5: 10.21254 | BM5: 10.21257 | BN5: 10.2126 | BO5: 10.21253 | BP5: 10.2125 | BQ5: 10.21231 | BR5: 10.21262 | BS5: 10.21272 | BT5: 10.21264 | BU5: 10.21263 | BV5: 10.21262 | BW5: 10.21271 | BX5: 10.2128 | BY5: 10.21272 | BZ5: 10.2127 | CA5: 10.21251 | CB5: 10.2127 | CC5: 10.21271 | CD5: 10.21269 | CE5: 10.21276 | CF5: 10.21252 | CG5: 10.21251 | CH5: 10.21241 | CI5: 10.21238 | CJ5: 10.21231 | CK5: 10.21281 | CL5: 10.2133 | CM5: 10.21324 | CN5: 10.21338 | CO5: 10.21333 | CP5: 10.21334 | CQ5: 10.2133 | CR5: 10.21327 | CS5: 10.21315 | CT5: 10.21328 | CU5: 10.21338 | CV5: 10.21334 | CW5: 10.21328 | CX5: 10.21319 | CY5: 10.21302 | CZ5: 10.21308 | DA5: 10.21295 | DB5: 10.21298 | DC5: 10.213 | DD5: 10.21305 | DE5: 10.2128 | DF5: 10.21268 | DG5: 10.21289 | DH5: 10.21329 | DI5: 10.21339 | DJ5: 10.2134 | DK5: 10.21316 | DL5: 10.21323 | DM5: 10.21314 | DN5: 10.21343 | DO5: 10.21319 | DP5: 10.21321 | DQ5: 10.21334 | DR5: 10.21329 | DS5: 10.21338 | DT5: 10.21314 | DU5: 10.21329 | DV5: 10.21332 | DW5: 10.21338 | DX5: 10.21325 | DY5: 10.21325 | EA5: YJGS2.2 | EB5: 10.58664 | EC5: 10.58629 | ED5: 10.58652 | EE5: 10.58673 | EF5: 10.58636 | EG5: 10.58615 | EH5: 10.58642 | EI5: 10.58631 | EJ5: 10.58624 | EK5: 10.58616 | EL5: 10.58641 | EM5: 10.2133 | EN5: 10.58598 | EO5: 10.58637 | EP5: 10.58664 | EQ5: 10.58633 | ER5: 10.58604 | ES5: 10.58636 | ET5: 10.21328 | EU5: 10.58694 | EV5: 10.58669 | EW5: 10.58691 | EX5: 10.58696 | EY5: 10.58663 | EZ5: 10.58625 | FA5: 10.21344 | FB5: 10.58653 | FC5: 10.58673 | FD5: 10.58705 | FE5: 10.58708 | FF5: 10.58717 | FG5: 10.21323 | FH5: 10.58717 | FI5: 10.58681 | FJ5: 10.5868 | FK5: 10.5867 | FL5: 10.58639 | FM5: 10.21328 | FN5: 10.586 | FO5: 10.58623 | FP5: 10.58613 | FQ5: 10.58626 | FR5: 10.58626 | FS5: 10.58664 | FT5: 10.58663 | FU5: 10.21321 | FV5: 10.58689 | FW5: 10.58669 | FX5: 10.21323 | FY5: 10.58684 | FZ5: 10.58689 | GA5: 10.58689 | GB5: 10.58675 | GC5: 10.58689 | GD5: 10.58726
A6: YJGC3-1 | B6: 10.16845 | C6: 10.16843 | D6: 10.16845 | E6: 10.16833 | F6: 10.16845 | G6: 10.16831 | H6: 10.16843 | I6: 10.16833 | J6: 10.16838 | K6: 10.16841 | L6: 10.16845 | M6: 10.16838 | N6: 10.16854 | O6: 10.16838 | P6: 10.1725 | Q6: 10.17255 | R6: 10.172001 | S6: 10.16973 | T6: 10.16966 | U6: 10.16984 | V6: 10.16979 | W6: 10.1719 | X6: 10.17198 | Y6: 10.17187 | Z6: 10.17175 | AA6: 10.17163 | AB6: 10.1715 | AC6: 10.17158 | AD6: 10.17166 | AE6: 10.17193 | AF6: 10.1722 | AG6: 10.17217 | AH6: 10.17213 | AI6: 10.17217 | AJ6: 10.1722 | AK6: 10.17232 | AL6: 10.17234 | AM6: 10.17228 | AN6: 10.17222 | AO6: 10.17246 | AP6: 10.1727 | AQ6: 10.17284 | AR6: 10.17289 | AS6: 10.17277 | AT6: 10.17305 | AU6: 10.17302 | AV6: 10.17317 | AW6: 10.17315 | AX6: 10.17314 | AY6: 10.17314 | AZ6: 10.17309 | BA6: 10.17295 | BB6: 10.17322 | BC6: 10.17322 | BD6: 10.17331 | BE6: 10.1731 | BF6: 10.17324 | BG6: 10.17325 | BH6: 10.17325 | BI6: 10.17336 | BJ6: 10.1734 | BK6: 10.17333 | BL6: 10.17326 | BM6: 10.17317 | BN6: 10.17308 | BO6: 10.17301 | BP6: 10.17298 | BQ6: 10.17299 | BR6: 10.17283 | BS6: 10.1727 | BT6: 10.17292 | BU6: 10.17289 | BV6: 10.17286 | BW6: 10.17288 | BX6: 10.1729 | BY6: 10.17289 | BZ6: 10.17294 | CA6: 10.17301 | CB6: 10.17298 | CC6: 10.17295 | CD6: 10.17305 | CE6: 10.17297 | CF6: 10.17286 | CG6: 10.17285 | CH6: 10.17275 | CI6: 10.17259 | CJ6: 10.17282 | CK6: 10.17321 | CL6: 10.1736 | CM6: 10.17351 | CN6: 10.17356 | CO6: 10.17359 | CP6: 10.17344 | CQ6: 10.17339 | CR6: 10.1734 | CS6: 10.17348 | CT6: 10.17347 | CU6: 10.17349 | CV6: 10.17325 | CW6: 10.17345 | CX6: 10.17335 | CY6: 10.17338 | CZ6: 10.17324 | DA6: 10.17346 | DB6: 10.17333 | DC6: 10.1732 | DD6: 10.17313 | DE6: 10.17306 | DF6: 10.17289 | DG6: 10.17303 | DH6: 10.17267 | DI6: 10.17282 | DJ6: 10.17281 | DK6: 10.17255 | DL6: 10.1726 | DM6: 10.17267 | DN6: 10.17268 | DO6: 10.1727 | DP6: 10.17261 | DQ6: 10.17276 | DR6: 10.17269 | DS6: 10.17281 | DT6: 10.17258 | DU6: 10.17281 | DV6: 10.17281 | DW6: 10.17281 | DX6: 10.17271 | DY6: 10.17264 | EA6: YJGS3.1 | EB6: 10.42404 | EC6: 10.42372 | ED6: 10.42387 | EE6: 10.42401 | EF6: 10.42441 | EG6: 10.42441 | EH6: 10.42464 | EI6: 10.4249 | EJ6: 10.42462 | EK6: 10.4245 | EL6: 10.42411 | EM6: 10.1728 | EN6: 10.42406 | EO6: 10.42385 | EP6: 10.42379 | EQ6: 10.42345 | ER6: 10.42346 | ES6: 10.42336 | ET6: 10.17268 | EU6: 10.42412 | EV6: 10.42424 | EW6: 10.42444 | EX6: 10.42417 | EY6: 10.42393 | EZ6: 10.4236 | FA6: 10.1728 | FB6: 10.42363 | FC6: 10.42395 | FD6: 10.42399 | FE6: 10.42368 | FF6: 10.424 | FG6: 10.17275 | FH6: 10.42368 | FI6: 10.42357 | FJ6: 10.42372 | FK6: 10.42367 | FL6: 10.4241 | FM6: 10.17253 | FN6: 10.42381 | FO6: 10.42347 | FP6: 10.4238 | FQ6: 10.42404 | FR6: 10.4242 | FS6: 10.42445 | FT6: 10.424 | FU6: 10.1727 | FV6: 10.42422 | FW6: 10.42416 | FX6: 10.17279 | FY6: 10.42441 | FZ6: 10.42434 | GA6: 10.42435 | GB6: 10.42424 | GC6: 10.42434 | GD6: 10.42448
A7: YJGC3-2 | B7: 10.3201 | C7: 10.32001 | D7: 10.3201 | E7: 10.32008 | F7: 10.32005 | G7: 10.31997 | H7: 10.32 | I7: 10.32011 | J7: 10.32009 | K7: 10.32003 | L7: 10.32006 | M7: 10.32004 | N7: 10.32035 | O7: 10.32004 | P7: 10.3244 | Q7: 10.32444 | R7: 10.324147 | S7: 10.32212 | T7: 10.32198 | U7: 10.32203 | V7: 10.32206 | W7: 10.3243 | X7: 10.32441 | Y7: 10.32456 | Z7: 10.3247 | AA7: 10.3244 | AB7: 10.3241 | AC7: 10.32406 | AD7: 10.32401 | AE7: 10.32446 | AF7: 10.3249 | AG7: 10.32486 | AH7: 10.32481 | AI7: 10.32501 | AJ7: 10.3252 | AK7: 10.32519 | AL7: 10.32538 | AM7: 10.32534 | AN7: 10.3253 | AO7: 10.32515 | AP7: 10.325 | AQ7: 10.32512 | AR7: 10.32486 | AS7: 10.32485 | AT7: 10.32473 | AU7: 10.32482 | AV7: 10.32489 | AW7: 10.32496 | AX7: 10.32505 | AY7: 10.32485 | AZ7: 10.325 | BA7: 10.32518 | BB7: 10.32503 | BC7: 10.32509 | BD7: 10.32502 | BE7: 10.32518 | BF7: 10.32487 | BG7: 10.32486 | BH7: 10.32485 | BI7: 10.32474 | BJ7: 10.32469 | BK7: 10.32471 | BL7: 10.32472 | BM7: 10.3248 | BN7: 10.32488 | BO7: 10.32522 | BP7: 10.32536 | BQ7: 10.32517 | BR7: 10.32541 | BS7: 10.32523 | BT7: 10.3255 | BU7: 10.32546 | BV7: 10.32541 | BW7: 10.32541 | BX7: 10.3254 | BY7: 10.32545 | BZ7: 10.32534 | CA7: 10.32517 | CB7: 10.3252 | CC7: 10.32504 | CD7: 10.32515 | CE7: 10.32498 | CF7: 10.32523 | CG7: 10.3251 | CH7: 10.32528 | CI7: 10.3252 | CJ7: 10.3252 | CK7: 10.32545 | CL7: 10.3257 | CM7: 10.32562 | CN7: 10.32575 | CO7: 10.32578 | CP7: 10.3257 | CQ7: 10.32569 | CR7: 10.32557 | CS7: 10.32574 | CT7: 10.32558 | CU7: 10.32574 | CV7: 10.3255 | CW7: 10.32557 | CX7: 10.32573 | CY7: 10.32566 | CZ7: 10.32554 | DA7: 10.32553 | DB7: 10.32552 | DC7: 10.3255 | DD7: 10.32534 | DE7: 10.32535 | DF7: 10.32528 | DG7: 10.32527 | DH7: 10.32512 | DI7: 10.32502 | DJ7: 10.32515 | DK7: 10.3251 | DL7: 10.32522 | DM7: 10.32521 | DN7: 10.32515 | DO7: 10.32523 | DP7: 10.32513 | DQ7: 10.32519 | DR7: 10.32516 | DS7: 10.32518 | DT7: 10.32497 | DU7: 10.32505 | DV7: 10.32505 | DW7: 10.32522 | DX7: 10.32508 | DY7: 10.32517 | EA7: YJGS3.2 | EB7: 10.94025 | EC7: 10.94008 | EE7: 10.9398 | EF7: 10.93999 | EG7: 10.94037 | EH7: 10.94024 | EI7: 10.94013 | EJ7: 10.94007 | EK7: 10.94049 | EM7: 10.32512 | EN7: 10.94038 | EO7: 10.94013 | EP7: 10.94047 | EQ7: 10.9403 | ER7: 10.94033 | ES7: 10.93994 | ET7: 10.32503 | EU7: 10.93992 | EV7: 10.93977 | EW7: 10.93983 | EX7: 10.94014 | EY7: 10.94034 | EZ7: 10.94031 | FA7: 10.32504 | FB7: 10.94038 | FC7: 10.94046 | FD7: 10.94023 | FE7: 10.93979 | FF7: 10.93992 | FG7: 10.32498 | FH7: 10.93987 | FI7: 10.93976 | FJ7: 10.93998 | FK7: 10.94002 | FL7: 10.9399 | FM7: 10.32505 | FN7: 10.93978 | FO7: 10.93976 | FP7: 10.93976 | FQ7: 10.93993 | FR7: 10.93996 | FS7: 10.93977 | FT7: 10.93961 | FU7: 10.32515 | FV7: 10.93973 | FW7: 10.93977 | FX7: 10.32514 | FY7: 10.93958 | FZ7: 10.93962 | GA7: 10.93967 | GB7: 10.9397 | GC7: 10.93962 | GD7: 10.93991
A8: YJGC4-1 | B8: 10.18645 | C8: 10.1863 | D8: 10.18635 | E8: 10.18637 | F8: 10.18634 | G8: 10.1863 | H8: 10.18634 | I8: 10.18635 | J8: 10.18631 | K8: 10.18634 | L8: 10.18639 | M8: 10.18624 | N8: 10.18636 | O8: 10.18624 | P8: 10.1905 | Q8: 10.19045 | R8: 10.189984 | S8: 10.18805 | T8: 10.18794 | U8: 10.18825 | V8: 10.1881 | W8: 10.1902 | X8: 10.19028 | Y8: 10.19031 | Z8: 10.19034 | AA8: 10.18997 | AB8: 10.1896 | AC8: 10.18964 | AD8: 10.18967 | AE8: 10.18984 | AF8: 10.19 | AG8: 10.19008 | AH8: 10.19015 | AI8: 10.19053 | AJ8: 10.1909 | AK8: 10.19108 | AL8: 10.19073 | AM8: 10.19075 | AN8: 10.19076 | AO8: 10.19093 | AP8: 10.1911 | AQ8: 10.19127 | AR8: 10.19096 | AS8: 10.19089 | AT8: 10.19106 | AU8: 10.19089 | AV8: 10.19116 | AW8: 10.19097 | AX8: 10.19115 | AY8: 10.19123 | AZ8: 10.19121 | BA8: 10.19116 | BB8: 10.19113 | BC8: 10.19102 | BD8: 10.1911 | BE8: 10.19126 | BF8: 10.19097 | BG8: 10.19114 | BH8: 10.19121 | BI8: 10.19129 | BJ8: 10.19133 | BK8: 10.19131 | BL8: 10.19128 | BM8: 10.19137 | BN8: 10.19145 | BO8: 10.19151 | BP8: 10.19154 | BQ8: 10.19169 | BR8: 10.19166 | BS8: 10.19168 | BT8: 10.19169 | BU8: 10.19162 | BV8: 10.19154 | BW8: 10.19132 | BX8: 10.1911 | BY8: 10.19097 | BZ8: 10.19118 | CA8: 10.19099 | CB8: 10.1911 | CC8: 10.1911 | CD8: 10.19116 | CE8: 10.19097 | CF8: 10.19111 | CG8: 10.19093 | CH8: 10.19118 | CI8: 10.19111 | CJ8: 10.19115 | CK8: 10.19148 | CL8: 10.1916 | CM8: 10.19148 | CN8: 10.19156 | CO8: 10.19153 | CP8: 10.19137 | CQ8: 10.19132 | CR8: 10.19125 | CS8: 10.1913 | CT8: 10.19119 | CU8: 10.19146 | CV8: 10.19142 | CW8: 10.19133 | CX8: 10.19117 | CY8: 10.19117 | CZ8: 10.19108 | DA8: 10.19114 | DB8: 10.19122 | DC8: 10.1913 | DD8: 10.19119 | DE8: 10.1912 | DF8: 10.19121 | DG8: 10.19126 | DH8: 10.19097 | DI8: 10.19096 | DJ8: 10.19086 | DK8: 10.19105 | DL8: 10.19107 | DM8: 10.19096 | DN8: 10.19086 | DO8: 10.1911 | DP8: 10.19101 | DQ8: 10.19099 | DR8: 10.19085 | DS8: 10.19107 | DT8: 10.19089 | DU8: 10.19093 | DV8: 10.1909 | DW8: 10.19109 | DX8: 10.19098 | DY8: 10.19084 | EA8: YJGS4.1 | EB8: 10.29549 | EC8: 10.29548 | ED8: 10.2952 | EE8: 10.29524 | EF8: 10.29558 | EG8: 10.29598 | EH8: 10.29579 | EI8: 10.29553 | EJ8: 10.29576 | EK8: 10.29581 | EL8: 10.2957 | EM8: 10.19104 | EN8: 10.29494 | EO8: 10.29508 | EP8: 10.29541 | EQ8: 10.29512 | ER8: 10.29523 | ES8: 10.29489 | ET8: 10.19083 | EU8: 10.29484 | EV8: 10.29485 | EW8: 10.29489 | EX8: 10.29486 | EY8: 10.29524 | EZ8: 10.29531 | FA8: 10.191 | FB8: 10.29564 | FC8: 10.29537 | FD8: 10.2956 | FE8: 10.29586 | FF8: 10.29602 | FG8: 10.19084 | FH8: 10.29594 | FI8: 10.296 | FJ8: 10.29562 | FK8: 10.29607 | FL8: 10.29605 | FM8: 10.19111 | FN8: 10.29598 | FO8: 10.29581 | FP8: 10.29588 | FQ8: 10.29589 | FR8: 10.29583 | FS8: 10.29556 | FT8: 10.2958 | FU8: 10.1911 | FV8: 10.29566 | FW8: 10.29564 | FX8: 10.19096 | FY8: 10.29564 | FZ8: 10.29578 | GA8: 10.29569 | GB8: 10.29603 | GC8: 10.29578 | GD8: 10.29575
A9: YJGC4-2 | B9: 10.35755 | C9: 10.35747 | D9: 10.35749 | E9: 10.3575 | F9: 10.35749 | G9: 10.35744 | H9: 10.35754 | I9: 10.35743 | J9: 10.35741 | K9: 10.35754 | L9: 10.35748 | M9: 10.35743 | N9: 10.35758 | O9: 10.35743 | P9: 10.3611 | Q9: 10.36124 | R9: 10.3612 | S9: 10.35911 | T9: 10.35909 | U9: 10.35917 | V9: 10.35905 | W9: 10.361 | X9: 10.36096 | Y9: 10.36099 | Z9: 10.36102 | AA9: 10.36081 | AB9: 10.3606 | AC9: 10.36085 | AD9: 10.3611 | AE9: 10.36115 | AF9: 10.3612 | AG9: 10.36117 | AH9: 10.36114 | AI9: 10.36147 | AJ9: 10.3618 | AK9: 10.3618 | AL9: 10.36162 | AM9: 10.36155 | AN9: 10.36148 | AO9: 10.36179 | AP9: 10.3621 | AQ9: 10.36218 | AR9: 10.36198 | AS9: 10.36192 | AT9: 10.36208 | AU9: 10.36226 | AV9: 10.3621 | AW9: 10.36206 | AX9: 10.36228 | AY9: 10.36214 | AZ9: 10.36218 | BA9: 10.36237 | BB9: 10.36213 | BC9: 10.36215 | BD9: 10.36234 | BE9: 10.36209 | BF9: 10.36232 | BG9: 10.36226 | BH9: 10.36223 | BI9: 10.36216 | BJ9: 10.36213 | BK9: 10.36207 | BL9: 10.362 | BM9: 10.36201 | BN9: 10.36201 | BO9: 10.36223 | BP9: 10.36233 | BQ9: 10.36226 | BR9: 10.36238 | BS9: 10.36224 | BT9: 10.36219 | BU9: 10.36214 | BV9: 10.36209 | BW9: 10.3622 | BX9: 10.3623 | BY9: 10.36224 | BZ9: 10.3623 | CA9: 10.3624 | CB9: 10.36214 | CC9: 10.36201 | CD9: 10.36217 | CE9: 10.362 | CF9: 10.36209 | CG9: 10.36206 | CH9: 10.36192 | CI9: 10.36184 | CJ9: 10.36198 | CK9: 10.36229 | CL9: 10.3626 | CM9: 10.36259 | CN9: 10.36257 | CO9: 10.36256 | CP9: 10.3625 | CQ9: 10.36237 | CR9: 10.36249 | CS9: 10.36248 | CT9: 10.36239 | CU9: 10.36245 | CV9: 10.36238 | CW9: 10.36242 | CX9: 10.36256 | CY9: 10.36247 | CZ9: 10.36244 | DA9: 10.36229 | DB9: 10.3623 | DC9: 10.3623 | DD9: 10.36214 | DE9: 10.3624 | DF9: 10.36244 | DG9: 10.36232 | DH9: 10.36242 | DI9: 10.3623 | DJ9: 10.36253 | DK9: 10.36243 | DL9: 10.3624 | DM9: 10.3624 | DN9: 10.3623 | DO9: 10.36238 | DP9: 10.3623 | DQ9: 10.36255 | DR9: 10.36233 | DS9: 10.36256 | DT9: 10.36249 | DU9: 10.36248 | DV9: 10.36254 | DW9: 10.36233 | DX9: 10.36239 | DY9: 10.36233 | EA9: YJGS4.2 | EB9: 10.72995 | EC9: 10.72988 | ED9: 10.72971 | EE9: 10.72981 | EF9: 10.72991 | EG9: 10.72947 | EH9: 10.72942 | EI9: 10.72925 | EJ9: 10.72963 | EK9: 10.73005 | EL9: 10.7305 | EM9: 10.36237 | EN9: 10.73057 | EO9: 10.73054 | EP9: 10.73037 | EQ9: 10.73055 | ER9: 10.7306 | ES9: 10.73064 | ET9: 10.36228 | EU9: 10.73011 | EV9: 10.72989 | EW9: 10.72982 | EX9: 10.73016 | EY9: 10.73006 | EZ9: 10.73053 | FA9: 10.36251 | FB9: 10.7304 | FC9: 10.73058 | FD9: 10.7303 | FE9: 10.7303 | FF9: 10.72994 | FG9: 10.3624 | FH9: 10.73018 | FI9: 10.73033 | FJ9: 10.73011 | FK9: 10.72976 | FL9: 10.73015 | FM9: 10.36256 | FN9: 10.73055 | FO9: 10.73049 | FP9: 10.73044 | FQ9: 10.73047 | FR9: 10.73044 | FS9: 10.73026 | FT9: 10.73014 | FU9: 10.3625 | FV9: 10.72981 | FW9: 10.73014 | FX9: 10.36243 | FY9: 10.73048 | FZ9: 10.73049 | GA9: 10.73022 | GB9: 10.73031 | GC9: 10.73049 | GD9: 10.73007
A10: YJGC5-1 | B10: 10.21965 | C10: 10.21965 | D10: 10.21966 | E10: 10.21964 | F10: 10.21951 | G10: 10.21951 | H10: 10.21958 | I10: 10.21956 | J10: 10.21963 | K10: 10.21965 | L10: 10.21951 | M10: 10.21942 | N10: 10.21964 | O10: 10.21942 | P10: 10.22385 | Q10: 10.22389 | R10: 10.223961 | S10: 10.22208 | T10: 10.22189 | U10: 10.22201 | V10: 10.22201 | W10: 10.2241 | X10: 10.22423 | Y10: 10.22423 | Z10: 10.22422 | AA10: 10.22396 | AB10: 10.2237 | AC10: 10.22366 | AD10: 10.22361 | AE10: 10.22446 | AF10: 10.2253 | AG10: 10.22535 | AH10: 10.22539 | AI10: 10.22515 | AJ10: 10.2249 | AK10: 10.22496 | AL10: 10.22478 | AM10: 10.22471 | AN10: 10.22463 | AO10: 10.22482 | AP10: 10.225 | AQ10: 10.22504 | AR10: 10.22513 | AS10: 10.225 | AT10: 10.22527 | AU10: 10.22527 | AV10: 10.22546 | AW10: 10.22551 | AX10: 10.22545 | AY10: 10.22526 | AZ10: 10.22539 | BA10: 10.22538 | BB10: 10.22562 | BC10: 10.22541 | BD10: 10.2253 | BE10: 10.22541 | BF10: 10.22549 | BG10: 10.22541 | BH10: 10.22538 | BI10: 10.22544 | BJ10: 10.22546 | BK10: 10.22548 | BL10: 10.2255 | BM10: 10.22548 | BN10: 10.22546 | BO10: 10.22563 | BP10: 10.2257 | BQ10: 10.22557 | BR10: 10.22563 | BS10: 10.22552 | BT10: 10.2256 | BU10: 10.22558 | BV10: 10.22555 | BW10: 10.22528 | BX10: 10.225 | BY10: 10.22509 | BZ10: 10.22494 | CA10: 10.22483 | CB10: 10.22494 | CC10: 10.22483 | CD10: 10.22483 | CE10: 10.22472 | CF10: 10.22489 | CG10: 10.22499 | CH10: 10.22475 | CI10: 10.22476 | CJ10: 10.22466 | CK10: 10.22493 | CL10: 10.2254 | CM10: 10.22522 | CN10: 10.22526 | CO10: 10.22514 | CP10: 10.22516 | CQ10: 10.22513 | CR10: 10.22499 | CS10: 10.22515 | CT10: 10.22526 | CU10: 10.22521 | CV10: 10.22521 | CW10: 10.2251 | CX10: 10.22502 | CY10: 10.22501 | CZ10: 10.22508 | DA10: 10.22495 | DB10: 10.22518 | DC10: 10.2253 | DD10: 10.22525 | DE10: 10.22537 | DF10: 10.22543 | DG10: 10.22546 | DH10: 10.22519 | DI10: 10.22512 | DJ10: 10.22525 | DK10: 10.22511 | DL10: 10.22534 | DM10: 10.22517 | DN10: 10.22509 | DO10: 10.22534 | DP10: 10.22517 | DQ10: 10.22519 | DR10: 10.22526 | DS10: 10.22517 | DT10: 10.22528 | DU10: 10.22515 | DV10: 10.22522 | DW10: 10.22527 | DX10: 10.22528 | DY10: 10.22515 | EA10: YJGS5.1 | EB10: 10.47343 | EC10: 10.47332 | ED10: 10.47304 | EE10: 10.4733 | EF10: 10.47326 | EG10: 10.47316 | EH10: 10.47299 | EI10: 10.47344 | EJ10: 10.47353 | EK10: 10.47388 | EL10: 10.47403 | EM10: 10.2252 | EN10: 10.4737 | EO10: 10.47356 | EP10: 10.47391 | EQ10: 10.47376 | ER10: 10.47364 | ES10: 10.47373 | ET10: 10.22511 | EU10: 10.47405 | EV10: 10.47389 | EW10: 10.47399 | EX10: 10.47386 | EY10: 10.47368 | EZ10: 10.47375 | FA10: 10.22519 | FB10: 10.47412 | FC10: 10.47389 | FD10: 10.47362 | FE10: 10.47338 | FF10: 10.47349 | FG10: 10.22531 | FH10: 10.4736 | FI10: 10.47334 | FJ10: 10.47348 | FK10: 10.47373 | FL10: 10.47412 | FM10: 10.22515 | FN10: 10.47388 | FO10: 10.47356 | FP10: 10.47354 | FQ10: 10.47327 | FR10: 10.47332 | FS10: 10.47303 | FT10: 10.47327 | FU10: 10.22517 | FV10: 10.47353 | FW10: 10.47338 | FX10: 10.22507 | FY10: 10.47317 | FZ10: 10.47282 | GA10: 10.47308 | GB10: 10.47306 | GC10: 10.47282 | GD10: 10.47323
A11: YJGC5-2 | B11: 10.34565 | C11: 10.34557 | D11: 10.34552 | E11: 10.34558 | F11: 10.34554 | G11: 10.34558 | H11: 10.34555 | I11: 10.34565 | J11: 10.34557 | K11: 10.34553 | L11: 10.34562 | M11: 10.34548 | N11: 10.34561 | O11: 10.34548 | P11: 10.34985 | Q11: 10.3499 | R11: 10.349482 | S11: 10.3486 | T11: 10.3484 | U11: 10.34863 | V11: 10.3485 | W11: 10.3503 | X11: 10.35033 | Y11: 10.35042 | Z11: 10.35051 | AA11: 10.35026 | AB11: 10.35 | AC11: 10.34995 | AD11: 10.3499 | AE11: 10.3507 | AF11: 10.3515 | AG11: 10.35157 | AH11: 10.35163 | AI11: 10.35152 | AJ11: 10.3514 | AK11: 10.35134 | AL11: 10.35133 | AM11: 10.35135 | AN11: 10.35137 | AO11: 10.35134 | AP11: 10.3513 | AQ11: 10.35126 | AR11: 10.35149 | AS11: 10.35167 | AT11: 10.35168 | AU11: 10.35154 | AV11: 10.3517 | AW11: 10.35164 | AX11: 10.35175 | AY11: 10.35165 | AZ11: 10.35171 | BA11: 10.3516 | BB11: 10.35171 | BC11: 10.35175 | BD11: 10.35192 | BE11: 10.3519 | BF11: 10.35192 | BG11: 10.35174 | BH11: 10.35166 | BI11: 10.35168 | BJ11: 10.35169 | BK11: 10.35168 | BL11: 10.35167 | BM11: 10.35176 | BN11: 10.35185 | BO11: 10.35182 | BP11: 10.3518 | BQ11: 10.3516 | BR11: 10.35194 | BS11: 10.35183 | BT11: 10.35184 | BU11: 10.35181 | BV11: 10.35178 | BW11: 10.35169 | BX11: 10.3516 | BY11: 10.3515 | BZ11: 10.3514 | CA11: 10.35134 | CB11: 10.35149 | CC11: 10.3514 | CD11: 10.3515 | CE11: 10.35141 | CF11: 10.35154 | CG11: 10.3516 | CH11: 10.35135 | CI11: 10.35123 | CJ11: 10.35129 | CK11: 10.35155 | CL11: 10.3518 | CM11: 10.35175 | CN11: 10.35167 | CO11: 10.35165 | CP11: 10.35148 | CQ11: 10.35149 | CR11: 10.35135 | CS11: 10.35158 | CT11: 10.35129 | CU11: 10.35131 | CV11: 10.3514 | CW11: 10.35135 | CX11: 10.35134 | CY11: 10.35123 | CZ11: 10.3512 | DA11: 10.35123 | DB11: 10.3517 | DC11: 10.3521 | DD11: 10.352 | DE11: 10.35204 | DF11: 10.35202 | DG11: 10.35213 | DH11: 10.35233 | DI11: 10.35231 | DJ11: 10.35248 | DK11: 10.35233 | DL11: 10.35239 | DM11: 10.35244 | DN11: 10.35238 | DO11: 10.35244 | DP11: 10.35222 | DQ11: 10.35237 | DR11: 10.35235 | DS11: 10.35225 | DT11: 10.35248 | DU11: 10.35222 | DV11: 10.3522 | DW11: 10.35235 | DX11: 10.35236 | DY11: 10.3524 | EA11: YJGS5.2 | EB11: 11.08903 | EC11: 11.08881 | ED11: 11.08885 | EE11: 11.08886 | EF11: 11.08934 | EG11: 11.08951 | EH11: 11.08953 | EI11: 11.08917 | EJ11: 11.08881 | EK11: 11.08895 | EL11: 11.08933 | EM11: 10.35244 | EN11: 11.08866 | EO11: 11.08898 | EP11: 11.08926 | EQ11: 11.08891 | ER11: 11.0886 | ES11: 11.08849 | ET11: 10.35235 | EU11: 11.08834 | EV11: 11.08843 | EW11: 11.0885 | EX11: 11.08872 | EY11: 11.0888 | EZ11: 11.08897 | FA11: 10.35221 | FB11: 11.08904 | FC11: 11.08858 | FD11: 11.0888 | FE11: 11.08859 | FF11: 11.08843 | FG11: 10.35221 | FH11: 11.08879 | FI11: 11.0891 | FJ11: 11.08914 | FK11: 11.08918 | FL11: 11.08935 | FM11: 10.35247 | FN11: 11.08948 | FO11: 11.08967 | FP11: 11.08933 | FQ11: 11.08898 | FR11: 11.08879 | FS11: 11.08866 | FT11: 11.08857 | FU11: 10.35226 | FV11: 11.08894 | FW11: 11.08855 | FX11: 10.35241 | FY11: 11.08874 | FZ11: 11.08872 | GA11: 11.08883 | GB11: 11.08865 | GC11: 11.08872
A12: YJGC6-1 | B12: 10.2198 | C12: 10.2198 | D12: 10.21978 | E12: 10.21972 | F12: 10.21972 | G12: 10.21974 | H12: 10.21978 | I12: 10.21974 | J12: 10.21971 | K12: 10.2197 | L12: 10.21968 | M12: 10.21953 | N12: 10.21989 | O12: 10.21953 | P12: 10.2239 | Q12: 10.22387 | R12: 10.223569 | S12: 10.22205 | T12: 10.22192 | U12: 10.22198 | V12: 10.222 | W12: 10.2233 | X12: 10.22348 | Y12: 10.22354 | Z12: 10.2236 | AA12: 10.22325 | AB12: 10.2229 | AC12: 10.2229 | AD12: 10.2229 | AE12: 10.2239 | AF12: 10.2249 | AG12: 10.2244 | AH12: 10.2239 | AI12: 10.2241 | AJ12: 10.2243 | AK12: 10.22435 | AL12: 10.22446 | AM12: 10.22449 | AN12: 10.22452 | AO12: 10.22461 | AP12: 10.2247 | AQ12: 10.22486 | AR12: 10.22475 | AS12: 10.22459 | AT12: 10.22492 | AU12: 10.22498 | AV12: 10.225 | AW12: 10.22501 | AX12: 10.22481 | AY12: 10.22476 | AZ12: 10.22482 | BA12: 10.22473 | BB12: 10.22474 | BC12: 10.22486 | BD12: 10.22491 | BE12: 10.22469 | BF12: 10.2248 | BG12: 10.22492 | BH12: 10.22497 | BI12: 10.22495 | BJ12: 10.22494 | BK12: 10.22486 | BL12: 10.22477 | BM12: 10.22477 | BN12: 10.22476 | BO12: 10.22505 | BP12: 10.22518 | BQ12: 10.22525 | BR12: 10.2253 | BS12: 10.22534 | BT12: 10.22533 | BU12: 10.22526 | BV12: 10.22518 | BW12: 10.22499 | BX12: 10.2248 | BY12: 10.22468 | BZ12: 10.2248 | CA12: 10.22479 | CB12: 10.22472 | CC12: 10.22471 | CD12: 10.22459 | CE12: 10.22458 | CF12: 10.22446 | CG12: 10.22444 | CH12: 10.2244 | CI12: 10.22432 | CJ12: 10.22431 | CK12: 10.2248 | CL12: 10.2252 | CM12: 10.22501 | CN12: 10.22519 | CO12: 10.22528 | CP12: 10.22511 | CQ12: 10.22504 | CR12: 10.22498 | CS12: 10.22521 | CT12: 10.22474 | CU12: 10.22503 | CV12: 10.2252 | CW12: 10.22519 | CX12: 10.2252 | CY12: 10.22538 | CZ12: 10.2252 | DA12: 10.22529 | DB12: 10.22535 | DC12: 10.2254 | DD12: 10.22527 | DE12: 10.22535 | DF12: 10.22535 | DG12: 10.22527 | DH12: 10.22561 | DI12: 10.2256 | DJ12: 10.22574 | DK12: 10.22549 | DL12: 10.22569 | DM12: 10.22569 | DN12: 10.22552 | DO12: 10.22562 | DP12: 10.22562 | DQ12: 10.22566 | DR12: 10.22576 | DS12: 10.22551 | DT12: 10.2256 | DU12: 10.22551 | DV12: 10.22568 | DW12: 10.22557 | DX12: 10.22565 | DY12: 10.22552 | EA12: YJGS6.1 | EB12: 10.36462 | EC12: 10.36445 | ED12: 10.36419 | EE12: 10.36438 | EF12: 10.36426 | EG12: 10.3645 | EH12: 10.36439 | EI12: 10.36419 | EJ12: 10.36415 | EK12: 10.36415 | EL12: 10.36452 | EM12: 10.22562 | EN12: 10.36522 | EO12: 10.36506 | EP12: 10.36497 | EQ12: 10.36521 | ER12: 10.36497 | ES12: 10.36518 | ET12: 10.22572 | EU12: 10.36499 | EV12: 10.36515 | EW12: 10.3652 | EX12: 10.36498 | EY12: 10.36471 | EZ12: 10.36483 | FA12: 10.2256 | FB12: 10.36482 | FC12: 10.36462 | FD12: 10.36471 | FE12: 10.36469 | FF12: 10.36455 | FG12: 10.2256 | FH12: 10.36453 | FI12: 10.36488 | FJ12: 10.36462 | FK12: 10.36434 | FL12: 10.36462 | FM12: 10.22566 | FN12: 10.36455 | FO12: 10.36457 | FP12: 10.36459 | FQ12: 10.36436 | FR12: 10.36441 | FS12: 10.36449 | FT12: 10.36427 | FU12: 10.22548 | FV12: 10.36439 | FW12: 10.36442 | FX12: 10.22555 | FY12: 10.36452 | FZ12: 10.36423 | GA12: 10.36439 | GB12: 10.36436 | GC12: 10.36423 | GD12: 10.36422
A13: YJGC6-2 | B13: 10.3464 | C13: 10.34632 | D13: 10.34631 | E13: 10.34638 | F13: 10.34628 | G13: 10.34637 | H13: 10.34634 | I13: 10.34638 | J13: 10.34625 | K13: 10.34629 | L13: 10.34629 | M13: 10.34616 | N13: 10.34637 | O13: 10.34616 | P13: 10.3512 | Q13: 10.35116 | R13: 10.351363 | S13: 10.34945 | T13: 10.34937 | U13: 10.34953 | V13: 10.34949 | W13: 10.351 | X13: 10.35106 | Y13: 10.35103 | Z13: 10.351 | AA13: 10.35085 | AB13: 10.3507 | AC13: 10.35074 | AD13: 10.35077 | AE13: 10.35164 | AF13: 10.3525 | AG13: 10.3522 | AH13: 10.3519 | AI13: 10.352 | AJ13: 10.3521 | AK13: 10.35202 | AL13: 10.35205 | AM13: 10.35196 | AN13: 10.35187 | AO13: 10.35204 | AP13: 10.3522 | AQ13: 10.35228 | AR13: 10.35222 | AS13: 10.35229 | AT13: 10.35232 | AU13: 10.35234 | AV13: 10.35247 | AW13: 10.35248 | AX13: 10.35239 | AY13: 10.35251 | AZ13: 10.35238 | BA13: 10.3524 | BB13: 10.35239 | BC13: 10.35243 | BD13: 10.35234 | BE13: 10.35238 | BF13: 10.3522 | BG13: 10.3524 | BH13: 10.35248 | BI13: 10.35236 | BJ13: 10.35231 | BK13: 10.35236 | BL13: 10.3524 | BM13: 10.35249 | BN13: 10.35258 | BO13: 10.35257 | BP13: 10.35257 | BQ13: 10.35259 | BR13: 10.35241 | BS13: 10.3525 | BT13: 10.35226 | BU13: 10.35222 | BV13: 10.35218 | BW13: 10.35239 | BX13: 10.3526 | BY13: 10.35259 | BZ13: 10.35247 | CA13: 10.35246 | CB13: 10.35249 | CC13: 10.35257 | CD13: 10.35247 | CE13: 10.35239 | CF13: 10.3523 | CG13: 10.35226 | CH13: 10.35238 | CI13: 10.35233 | CJ13: 10.35243 | CK13: 10.35262 | CL13: 10.3528 | CM13: 10.35274 | CN13: 10.35281 | CO13: 10.35278 | CP13: 10.35263 | CQ13: 10.3525 | CR13: 10.35248 | CS13: 10.35244 | CT13: 10.35252 | CU13: 10.35246 | CV13: 10.35243 | CW13: 10.35261 | CX13: 10.3527 | CY13: 10.35252 | CZ13: 10.35245 | DA13: 10.35238 | DB13: 10.35269 | DC13: 10.353 | DD13: 10.35302 | DE13: 10.35303 | DF13: 10.35309 | DG13: 10.35289 | DH13: 10.3533 | DI13: 10.35334 | DJ13: 10.35332 | DK13: 10.35315 | DL13: 10.35323 | DM13: 10.35316 | DN13: 10.35323 | DO13: 10.35319 | DP13: 10.3534 | DQ13: 10.35332 | DR13: 10.35336 | DS13: 10.35329 | DT13: 10.35328 | DU13: 10.35342 | DV13: 10.35329 | DW13: 10.35344 | DX13: 10.35344 | DY13: 10.35323 | EA13: YJGS6.2 | EB13: 11.02602 | EC13: 11.02588 | ED13: 11.02572 | EE13: 11.02597 | EF13: 11.02645 | EG13: 11.02644 | EH13: 11.02632 | EI13: 11.02586 | EJ13: 11.02562 | EK13: 11.02546 | EL13: 11.02562 | EM13: 10.3532 | EN13: 11.02552 | EO13: 11.02551 | EP13: 11.02574 | EQ13: 11.02613 | ER13: 11.02572 | ES13: 11.026 | ET13: 10.35328 | EU13: 11.02532 | EV13: 11.02533 | EW13: 11.02556 | EX13: 11.02568 | EY13: 11.02611 | EZ13: 11.02626 | FA13: 10.35329 | FB13: 11.02594 | FC13: 11.02574 | FD13: 11.02588 | FE13: 11.02546 | FF13: 11.02591 | FG13: 10.35335 | FH13: 11.02577 | FI13: 11.02572 | FJ13: 11.02585 | FK13: 11.02615 | FL13: 11.02629 | FM13: 10.35342 | FN13: 11.02594 | FO13: 11.02625 | FP13: 11.02631 | FQ13: 11.02594 | FR13: 11.02593 | FS13: 11.02583 | FT13: 11.02605 | FU13: 10.3533 | FV13: 11.02618 | FW13: 11.02634 | FX13: 10.35333 | FY13: 11.02599 | FZ13: 11.02627 | GA13: 11.02633 | GB13: 11.02645 | GC13: 11.02627 | GD13: 11.02636
A14: YJGC7-1 | B14: 10.25205 | C14: 10.25196 | D14: 10.25199 | E14: 10.25192 | F14: 10.25198 | G14: 10.25197 | H14: 10.25192 | I14: 10.25203 | J14: 10.2519 | K14: 10.25199 | L14: 10.25205 | M14: 10.25203 | N14: 10.25217 | O14: 10.25203 | P14: 10.2561 | Q14: 10.25623 | R14: 10.255618 | S14: 10.25507 | T14: 10.25489 | U14: 10.25506 | V14: 10.25501 | W14: 10.25612 | X14: 10.25604 | Y14: 10.25593 | Z14: 10.25582 | AA14: 10.25596 | AB14: 10.2561 | AC14: 10.25617 | AD14: 10.25624 | AE14: 10.25667 | AF14: 10.2571 | AG14: 10.25718 | AH14: 10.25726 | AI14: 10.25698 | AJ14: 10.2567 | AK14: 10.25672 | AL14: 10.2568 | AM14: 10.25684 | AN14: 10.25688 | AO14: 10.25694 | AP14: 10.257 | AQ14: 10.25692 | AR14: 10.2571 | AS14: 10.2572 | AT14: 10.25724 | AU14: 10.25744 | AV14: 10.25713 | AW14: 10.25704 | AX14: 10.25712 | AY14: 10.25694 | AZ14: 10.25723 | BA14: 10.25696 | BB14: 10.25703 | BC14: 10.25716 | BD14: 10.25701 | BE14: 10.25721 | BF14: 10.25705 | BG14: 10.25722 | BH14: 10.25729 | BI14: 10.25723 | BJ14: 10.2572 | BK14: 10.25716 | BL14: 10.25711 | BM14: 10.25712 | BN14: 10.25713 | BO14: 10.25789 | BP14: 10.25821 | BQ14: 10.25825 | BR14: 10.25825 | BS14: 10.25834 | BT14: 10.25816 | BU14: 10.25768 | BV14: 10.2572 | BW14: 10.25735 | BX14: 10.2575 | BY14: 10.25734 | BZ14: 10.25737 | CA14: 10.25761 | CB14: 10.25784 | CC14: 10.25779 | CD14: 10.25773 | CE14: 10.25787 | CF14: 10.258 | CG14: 10.2578 | CH14: 10.25808 | CI14: 10.25807 | CJ14: 10.25798 | CK14: 10.25779 | CL14: 10.2576 | CM14: 10.25767 | CN14: 10.25753 | CO14: 10.25767 | CP14: 10.2578 | CQ14: 10.25768 | CR14: 10.25779 | CS14: 10.25776 | CT14: 10.25771 | CU14: 10.25776 | CV14: 10.25777 | CW14: 10.2578 | CX14: 10.25766 | CY14: 10.2577 | CZ14: 10.25774 | DA14: 10.25776 | DB14: 10.25803 | DC14: 10.2583 | DD14: 10.2579 | DE14: 10.2575 | DF14: 10.25745 | DG14: 10.25756 | DH14: 10.25768 | DI14: 10.25781 | DJ14: 10.25774 | DK14: 10.25763 | DL14: 10.25768 | DM14: 10.25766 | DN14: 10.25757 | DO14: 10.2577 | DP14: 10.25782 | DQ14: 10.25766 | DR14: 10.25783 | DS14: 10.25759 | DT14: 10.25768 | DU14: 10.2576 | DV14: 10.25765 | DW14: 10.25754 | DX14: 10.25755 | DY14: 10.2576 | EA14: YJGS7.1 | EB14: 10.46489 | EC14: 10.46462 | ED14: 10.46443 | EE14: 10.46476 | EF14: 10.46461 | EG14: 10.46484 | EH14: 10.46512 | EI14: 10.4654 | EJ14: 10.46536 | EK14: 10.46535 | EL14: 10.46524 | EM14: 10.25767 | EN14: 10.4655 | EO14: 10.46535 | EP14: 10.4651 | EQ14: 10.46512 | ER14: 10.46542 | ES14: 10.46537 | ET14: 10.25779 | EU14: 10.46519 | EV14: 10.46515 | EW14: 10.4652 | EX14: 10.46518 | EY14: 10.46543 | EZ14: 10.46497 | FA14: 10.25773 | FB14: 10.46478 | FC14: 10.46461 | FD14: 10.46499 | FE14: 10.46515 | FF14: 10.46526 | FG14: 10.25782 | FH14: 10.465 | FI14: 10.46487 | FJ14: 10.46505 | FK14: 10.46502 | FL14: 10.46471 | FM14: 10.25756 | FN14: 10.4648 | FO14: 10.46434 | FP14: 10.46449 | FQ14: 10.46439 | FR14: 10.46446 | FS14: 10.46473 | FT14: 10.4647 | FU14: 10.25775 | FV14: 10.46505 | FW14: 10.46504 | FX14: 10.25774 | FY14: 10.46523 | FZ14: 10.46514 | GA14: 10.46507 | GB14: 10.465 | GC14: 10.46484 | GD14: 10.46476
A15: YJGC7-2 | B15: 10.34325 | C15: 10.3431 | D15: 10.34315 | E15: 10.3432 | F15: 10.34312 | G15: 10.34326 | H15: 10.34322 | I15: 10.34322 | J15: 10.34323 | K15: 10.34318 | L15: 10.34318 | M15: 10.34319 | N15: 10.34326 | O15: 10.34319 | P15: 10.3477 | Q15: 10.34768 | R15: 10.347486 | S15: 10.34628 | T15: 10.34626 | U15: 10.34634 | V15: 10.34648 | W15: 10.3477 | X15: 10.34779 | Y15: 10.34774 | Z15: 10.34769 | AA15: 10.3477 | AB15: 10.3477 | AC15: 10.34778 | AD15: 10.34786 | AE15: 10.34838 | AF15: 10.3489 | AG15: 10.34893 | AH15: 10.34896 | AI15: 10.34878 | AJ15: 10.3486 | AK15: 10.34861 | AL15: 10.34846 | AM15: 10.34846 | AN15: 10.34846 | AO15: 10.34863 | AP15: 10.3488 | AQ15: 10.34884 | AR15: 10.34872 | AS15: 10.34882 | AT15: 10.34854 | AU15: 10.34841 | AV15: 10.34839 | AW15: 10.34823 | AX15: 10.34828 | AY15: 10.34845 | AZ15: 10.34814 | BA15: 10.34818 | BB15: 10.34841 | BC15: 10.34829 | BD15: 10.3482 | BE15: 10.34833 | BF15: 10.34825 | BG15: 10.34879 | BH15: 10.34902 | BI15: 10.34889 | BJ15: 10.34883 | BK15: 10.34888 | BL15: 10.34892 | BM15: 10.34894 | BN15: 10.34896 | BO15: 10.3495 | BP15: 10.34973 | BQ15: 10.34973 | BR15: 10.3497 | BS15: 10.34975 | BT15: 10.34952 | BU15: 10.34921 | BV15: 10.3489 | BW15: 10.3491 | BX15: 10.3493 | BY15: 10.34921 | BZ15: 10.34938 | CA15: 10.3493 | CB15: 10.34946 | CC15: 10.34927 | CD15: 10.34953 | CE15: 10.34947 | CF15: 10.3494 | CG15: 10.34947 | CH15: 10.34924 | CI15: 10.34914 | CJ15: 10.34929 | CK15: 10.34915 | CL15: 10.349 | CM15: 10.34907 | CN15: 10.34886 | CO15: 10.34903 | CP15: 10.3492 | CQ15: 10.34906 | CR15: 10.34924 | CS15: 10.34908 | CT15: 10.34926 | CU15: 10.34912 | CV15: 10.34901 | CW15: 10.34906 | CX15: 10.34908 | CY15: 10.3491 | CZ15: 10.34916 | DA15: 10.34916 | DB15: 10.34948 | DC15: 10.3498 | DD15: 10.3495 | DE15: 10.3492 | DF15: 10.34917 | DG15: 10.34903 | DH15: 10.34875 | DI15: 10.34893 | DJ15: 10.3489 | DK15: 10.34867 | DL15: 10.3488 | DM15: 10.34874 | DN15: 10.34875 | DO15: 10.34889 | DP15: 10.34875 | DQ15: 10.34871 | DR15: 10.34884 | DS15: 10.3488 | DT15: 10.34874 | DU15: 10.34877 | DV15: 10.34876 | DW15: 10.34878 | DX15: 10.34865 | DY15: 10.34863 | EA15: YJGS7.2 | EB15: 11.08085 | EC15: 11.08068 | ED15: 11.08037 | EE15: 11.08075 | EF15: 11.08106 | EG15: 11.08088 | EH15: 11.081 | EI15: 11.08054 | EJ15: 11.08038 | EK15: 11.08029 | EL15: 11.08045 | EM15: 10.34868 | EN15: 11.08086 | EO15: 11.08133 | EP15: 11.08124 | EQ15: 11.08152 | ER15: 11.08142 | ES15: 11.08096 | ET15: 10.34881 | EU15: 11.08076 | EV15: 11.08067 | EW15: 11.08079 | EX15: 11.08055 | EY15: 11.0807 | EZ15: 11.08063 | FA15: 10.34889 | FB15: 11.08086 | FC15: 11.08092 | FD15: 11.08108 | FE15: 11.08102 | FF15: 11.08128 | FG15: 10.34862 | FH15: 11.08119 | FI15: 11.08111 | FJ15: 11.0807 | FK15: 11.08108 | FL15: 11.08102 | FM15: 10.34879 | FN15: 11.08083 | FO15: 11.08067 | FP15: 11.08031 | FQ15: 11.08019 | FR15: 11.08048 | FS15: 11.08063 | FT15: 11.0805 | FU15: 10.34886 | FV15: 11.08022 | FW15: 11.08031 | FX15: 10.34881 | FY15: 11.08026 | FZ15: 11.08067 | GA15: 11.0805 | GB15: 11.08054 | GC15: 11.08067
A16: YJGC8-1 | B16: 10.28365 | C16: 10.28355 | D16: 10.28363 | E16: 10.28353 | F16: 10.28363 | G16: 10.28361 | H16: 10.2836 | I16: 10.2836 | J16: 10.28356 | K16: 10.28359 | L16: 10.28358 | M16: 10.28349 | N16: 10.28359 | O16: 10.28349 | P16: 10.2874 | Q16: 10.28743 | R16: 10.287074 | S16: 10.28614 | T16: 10.2861 | U16: 10.28611 | V16: 10.28624 | W16: 10.2874 | X16: 10.28746 | Y16: 10.28733 | Z16: 10.2872 | AA16: 10.2874 | AB16: 10.2876 | AC16: 10.28785 | AD16: 10.2881 | AE16: 10.2885 | AF16: 10.2889 | AG16: 10.2889 | AH16: 10.28889 | AI16: 10.28855 | AJ16: 10.2882 | AK16: 10.28818 | AL16: 10.28815 | AM16: 10.28811 | AN16: 10.28806 | AO16: 10.28843 | AP16: 10.2888 | AQ16: 10.28891 | AR16: 10.28883 | AS16: 10.28871 | AT16: 10.28894 | AU16: 10.28902 | AV16: 10.28894 | AW16: 10.28889 | AX16: 10.28898 | AY16: 10.28914 | AZ16: 10.2891 | BA16: 10.28906 | BB16: 10.28907 | BC16: 10.28899 | BD16: 10.28888 | BE16: 10.28881 | BF16: 10.28897 | BG16: 10.28898 | BH16: 10.28898 | BI16: 10.28911 | BJ16: 10.28916 | BK16: 10.28926 | BL16: 10.28935 | BM16: 10.28927 | BN16: 10.28918 | BO16: 10.28951 | BP16: 10.28965 | BQ16: 10.28948 | BR16: 10.2896 | BS16: 10.28956 | BT16: 10.28963 | BU16: 10.28959 | BV16: 10.28955 | BW16: 10.28928 | BX16: 10.289 | BY16: 10.28894 | BZ16: 10.28885 | CA16: 10.28884 | CB16: 10.28872 | CC16: 10.28859 | CD16: 10.28865 | CE16: 10.28866 | CF16: 10.28848 | CG16: 10.28854 | CH16: 10.28846 | CI16: 10.28844 | CJ16: 10.28848 | CK16: 10.28889 | CL16: 10.2893 | CM16: 10.28939 | CN16: 10.28937 | CO16: 10.28926 | CP16: 10.28936 | CQ16: 10.28937 | CR16: 10.2892 | CS16: 10.28925 | CT16: 10.28938 | CU16: 10.28941 | CV16: 10.28927 | CW16: 10.28926 | CX16: 10.28933 | CY16: 10.28936 | CZ16: 10.28938 | DA16: 10.28921 | DB16: 10.28966 | DC16: 10.2901 | DD16: 10.29002 | DE16: 10.28999 | DF16: 10.2898 | DG16: 10.29003 | DH16: 10.28978 | DI16: 10.28987 | DJ16: 10.28971 | DK16: 10.28976 | DL16: 10.28993 | DM16: 10.2899 | DN16: 10.28983 | DO16: 10.28987 | DP16: 10.28965 | DQ16: 10.28965 | DR16: 10.28975 | DS16: 10.28968 | DT16: 10.28985 | DU16: 10.28978 | DV16: 10.28966 | DW16: 10.28976 | DX16: 10.28974 | DY16: 10.2898 | EA16: YJGS8.1 | EB16: 10.38282 | EC16: 10.38263 | ED16: 10.38239 | EE16: 10.38273 | EF16: 10.38268 | EG16: 10.38237 | EH16: 10.38254 | EI16: 10.38281 | EJ16: 10.38301 | EK16: 10.38311 | EL16: 10.38318 | EM16: 10.28991 | EN16: 10.38304 | EO16: 10.38328 | EP16: 10.38341 | EQ16: 10.38349 | ER16: 10.38367 | ES16: 10.38351 | ET16: 10.28966 | EU16: 10.38331 | EV16: 10.38291 | EW16: 10.38287 | EX16: 10.38273 | EY16: 10.38278 | EZ16: 10.38271 | FA16: 10.28981 | FB16: 10.38273 | FC16: 10.38249 | FD16: 10.38242 | FE16: 10.38233 | FF16: 10.38258 | FG16: 10.28972 | FH16: 10.38253 | FI16: 10.38273 | FJ16: 10.38272 | FK16: 10.38263 | FL16: 10.38236 | FM16: 10.28984 | FN16: 10.3824 | FO16: 10.38259 | FP16: 10.38288 | FQ16: 10.38252 | FR16: 10.3828 | FS16: 10.38285 | FT16: 10.38299 | FU16: 10.28987 | FV16: 10.38292 | FW16: 10.38318 | FX16: 10.28985 | FY16: 10.38327 | FZ16: 10.38333 | GA16: 10.38334 | GB16: 10.38316 | GC16: 10.38333 | GD16: 10.38337
A17: YJGC8-2 | B17: 10.42225 | C17: 10.42214 | D17: 10.42222 | E17: 10.42217 | F17: 10.42215 | G17: 10.42216 | H17: 10.42212 | I17: 10.42215 | J17: 10.42219 | K17: 10.42217 | L17: 10.42217 | M17: 10.42206 | N17: 10.42227 | O17: 10.42206 | P17: 10.4267 | Q17: 10.42678 | R17: 10.426162 | S17: 10.42526 | T17: 10.42509 | U17: 10.42532 | V17: 10.42523 | W17: 10.4267 | X17: 10.42674 | Y17: 10.42667 | Z17: 10.4266 | AA17: 10.4267 | AB17: 10.4268 | AC17: 10.427 | AD17: 10.4272 | AE17: 10.42775 | AF17: 10.4283 | AG17: 10.42839 | AH17: 10.42848 | AI17: 10.42809 | AJ17: 10.4277 | AK17: 10.42767 | AL17: 10.42761 | AM17: 10.42753 | AN17: 10.42745 | AO17: 10.42783 | AP17: 10.4282 | AQ17: 10.4283 | AR17: 10.42803 | AS17: 10.42821 | AT17: 10.42807 | AU17: 10.42813 | AV17: 10.42793 | AW17: 10.42774 | AX17: 10.42806 | AY17: 10.42786 | AZ17: 10.42802 | BA17: 10.42795 | BB17: 10.42823 | BC17: 10.42795 | BD17: 10.42806 | BE17: 10.42821 | BF17: 10.42807 | BG17: 10.42796 | BH17: 10.42791 | BI17: 10.42804 | BJ17: 10.4281 | BK17: 10.42811 | BL17: 10.42812 | BM17: 10.4282 | BN17: 10.42828 | BO17: 10.42856 | BP17: 10.42868 | BQ17: 10.4285 | BR17: 10.42862 | BS17: 10.42851 | BT17: 10.42862 | BU17: 10.42862 | BV17: 10.42861 | BW17: 10.42856 | BX17: 10.4285 | BY17: 10.42837 | BZ17: 10.4286 | CA17: 10.4285 | CB17: 10.42846 | CC17: 10.42833 | CD17: 10.42831 | CE17: 10.42823 | CF17: 10.4283 | CG17: 10.4283 | CH17: 10.42836 | CI17: 10.42829 | CJ17: 10.42822 | CK17: 10.42831 | CL17: 10.4284 | CM17: 10.42825 | CN17: 10.42837 | CO17: 10.42833 | CP17: 10.42818 | CQ17: 10.42826 | CR17: 10.42801 | CS17: 10.42812 | CT17: 10.42802 | CU17: 10.42815 | CV17: 10.42811 | CW17: 10.42802 | CX17: 10.42804 | CY17: 10.42785 | CZ17: 10.42771 | DA17: 10.42777 | DB17: 10.42804 | DC17: 10.4283 | DD17: 10.4284 | DE17: 10.4285 | DF17: 10.42847 | DG17: 10.42842 | DH17: 10.42808 | DI17: 10.42802 | DJ17: 10.42817 | DK17: 10.4282 | DL17: 10.42803 | DM17: 10.42807 | DN17: 10.42812 | DO17: 10.42807 | DP17: 10.42804 | DQ17: 10.42798 | DR17: 10.42813 | DS17: 10.42816 | DT17: 10.42807 | DU17: 10.42803 | DV17: 10.42794 | DW17: 10.42798 | DX17: 10.428 | DY17: 10.42803 | EA17: YJGS8.2 | EB17: 11.13359 | EC17: 11.13351 | ED17: 11.13308 | EE17: 11.13345 | EF17: 11.13382 | EG17: 11.13427 | EH17: 11.13379 | EI17: 11.13348 | EJ17: 11.13362 | EK17: 11.13373 | EL17: 11.13399 | EM17: 10.42816 | EN17: 11.13427 | EO17: 11.13401 | EP17: 11.13365 | EQ17: 11.13366 | ER17: 11.13391 | ES17: 11.13365 | ET17: 10.42799 | EU17: 11.13357 | EV17: 11.13336 | EW17: 11.13323 | EX17: 11.13332 | EY17: 11.13374 | EZ17: 11.13401 | FA17: 10.42817 | FB17: 11.13408 | FC17: 11.1342 | FD17: 11.1339 | FE17: 11.13361 | FF17: 11.13331 | FG17: 10.42802 | FH17: 11.13304 | FI17: 11.13321 | FJ17: 11.13337 | FK17: 11.13346 | FL17: 11.13377 | FM17: 10.42819 | FN17: 11.13403 | FO17: 11.13392 | FP17: 11.13409 | FQ17: 11.1338 | FR17: 11.13351 | FS17: 11.13363 | FT17: 11.13406 | FU17: 10.42814 | FV17: 11.13421 | FW17: 11.13406 | FX17: 10.42809 | FY17: 11.1338 | FZ17: 11.13399 | GA17: 11.13405 | GB17: 11.13398 | GC17: 11.13399 | GD17: 11.13413
A18: YJGC9-1 | B18: 10.2499 | C18: 10.24978 | D18: 10.2499 | E18: 10.24989 | F18: 10.24988 | G18: 10.2499 | H18: 10.24989 | I18: 10.24977 | J18: 10.24977 | K18: 10.24982 | L18: 10.24981 | M18: 10.24976 | N18: 10.24977 | O18: 10.24976 | P18: 10.2538 | Q18: 10.25387 | R18: 10.253595 | S18: 10.25189 | T18: 10.2517 | U18: 10.25191 | V18: 10.25189 | W18: 10.2533 | X18: 10.25342 | Y18: 10.25347 | Z18: 10.25351 | AA18: 10.25351 | AB18: 10.2535 | AC18: 10.25353 | AD18: 10.25356 | AE18: 10.25413 | AF18: 10.2547 | AG18: 10.25466 | AH18: 10.25461 | AI18: 10.25461 | AJ18: 10.25461 | AK18: 10.25465 | AL18: 10.25453 | AM18: 10.25463 | AN18: 10.25472 | AO18: 10.25476 | AP18: 10.2548 | AQ18: 10.25468 | AR18: 10.25485 | AS18: 10.25469 | AT18: 10.25476 | AU18: 10.25481 | AV18: 10.25466 | AW18: 10.25478 | AX18: 10.25479 | AY18: 10.25491 | AZ18: 10.2548 | BA18: 10.25472 | BB18: 10.25463 | BC18: 10.25478 | BD18: 10.25491 | BE18: 10.25472 | BF18: 10.25472 | BG18: 10.25477 | BH18: 10.25479 | BI18: 10.25478 | BJ18: 10.25478 | BK18: 10.2547 | BL18: 10.25462 | BM18: 10.25469 | BN18: 10.25476 | BO18: 10.25533 | BP18: 10.25557 | BQ18: 10.25559 | BR18: 10.25565 | BS18: 10.25568 | BT18: 10.25574 | BU18: 10.25578 | BV18: 10.25581 | BW18: 10.25596 | BX18: 10.2561 | BY18: 10.2561 | BZ18: 10.25602 | CA18: 10.25594 | CB18: 10.25594 | CC18: 10.25589 | CD18: 10.25576 | CE18: 10.25561 | CF18: 10.2558 | CG18: 10.25565 | CH18: 10.25587 | CI18: 10.25589 | CJ18: 10.25581 | CK18: 10.2557 | CL18: 10.25583 | CM18: 10.25592 | CN18: 10.25572 | CO18: 10.25581 | CP18: 10.25574 | CQ18: 10.25581 | CR18: 10.25556 | CS18: 10.25571 | CT18: 10.25557 | CU18: 10.25577 | CV18: 10.25563 | CW18: 10.25567 | CX18: 10.2558 | CY18: 10.25581 | CZ18: 10.25566 | DA18: 10.25571 | DB18: 10.25586 | DC18: 10.256 | DD18: 10.25603 | DE18: 10.25586 | DF18: 10.25589 | DG18: 10.25585 | DH18: 10.25569 | DI18: 10.25575 | DJ18: 10.25579 | DK18: 10.25556 | DL18: 10.25581 | DM18: 10.25557 | DN18: 10.25583 | DO18: 10.25573 | DP18: 10.25579 | DQ18: 10.25555 | DR18: 10.25578 | DS18: 10.2558 | DT18: 10.25576 | DU18: 10.25573 | DV18: 10.25557 | DW18: 10.25562 | DX18: 10.25559 | DY18: 10.25581 | EA18: YJGS9.1 | EB18: 10.63484 | EC18: 10.63467 | ED18: 10.63434 | EE18: 10.63472 | EF18: 10.6349 | EG18: 10.63497 | EH18: 10.6347 | EI18: 10.63453 | EJ18: 10.63459 | EK18: 10.6344 | EL18: 10.63453 | EM18: 10.25581 | EN18: 10.63478 | EO18: 10.635 | EP18: 10.63496 | EQ18: 10.63504 | ER18: 10.6346 | ES18: 10.63497 | ET18: 10.25558 | EU18: 10.63442 | EV18: 10.63434 | EW18: 10.63444 | EX18: 10.63477 | EY18: 10.63511 | EZ18: 10.63523 | FA18: 10.25567 | FB18: 10.63515 | FC18: 10.63517 | FD18: 10.63474 | FE18: 10.63462 | FF18: 10.63454 | FG18: 10.25555 | FH18: 10.63426 | FI18: 10.63408 | FJ18: 10.6341 | FK18: 10.63421 | FL18: 10.63402 | FM18: 10.25558 | FN18: 10.63406 | FO18: 10.63414 | FP18: 10.63439 | FQ18: 10.63452 | FR18: 10.63498 | FS18: 10.6354 | FT18: 10.63513 | FU18: 10.25573 | FV18: 10.63541 | FW18: 10.63548 | FX18: 10.25565 | FY18: 10.63557 | FZ18: 10.63519 | GA18: 10.63517 | GB18: 10.63518 | GC18: 10.63519 | GD18: 10.63498
